ERROR dict_args.py:413:vallidate_dict requires existing dictionary; no validation
